<robot
  name="mobi_head_urdf">
  <link
    name="base_link">
    <inertial>
      <origin
        xyz="0 0.0018045 -0.039994"
        rpy="0 0 0" />
      <mass
        value="0.3555" />
      <inertia
        ixx="0.00040436"
        ixy="3.4016E-20"
        ixz="-9.0031E-21"
        iyy="0.000405"
        iyz="-1.3023E-07"
        izz="0.00075624" />
    </inertial>
    <visual>
      <origin
        xyz="0 0 0"
        rpy="0 0 0" />
      <geometry>
        <mesh
          filename="package://mobi_head/urdf/meshes/base_link.STL" />
      </geometry>
      <material
        name="">
        <color
          rgba="0 0 0 1" />
      </material>
    </visual>
    <collision>
      <origin
        xyz="0 0 0"
        rpy="0 0 0" />
      <geometry>
        <mesh
          filename="package://mobi_head/urdf/meshes/base_link.STL" />
      </geometry>
    </collision>
  </link>
  <link
    name="Neck_Pan_Link">
    <inertial>
      <origin
        xyz="0.00058898 -0.00894 -6.4615E-05"
        rpy="0 0 0" />
      <mass
        value="0.09" />
      <inertia
        ixx="1.3697E-05"
        ixy="2.8421E-07"
        ixz="2.5442E-09"
        iyy="8.9996E-06"
        iyz="1.7691E-07"
        izz="1.1467E-05" />
    </inertial>
    <visual>
      <origin
        xyz="0 0 0"
        rpy="0 0 0" />
      <geometry>
        <mesh
          filename="package://mobi_head/urdf/meshes/Neck_Pan_Link.STL" />
      </geometry>
      <material
        name="">
        <color
          rgba="0.1569 0.1569 0.1569 1" />
      </material>
    </visual>
    <collision>
      <origin
        xyz="0 0 0"
        rpy="0 0 0" />
      <geometry>
        <mesh
          filename="package://mobi_head/urdf/meshes/Neck_Pan_Link.STL" />
      </geometry>
    </collision>
  </link>
  <joint
    name="Neck_Pan_Joint"
    type="revolute">
    <origin
      xyz="0 0 0"
      rpy="0 1.5708 0" />
    <parent
      link="base_link" />
    <child
      link="Neck_Pan_Link" />
    <axis
      xyz="-1 0 0" />
    <limit
      lower="-1.5708"
      upper="1.5708"
      effort="3.1"
      velocity="3.1416" />
  </joint>
  <link
    name="Neck_Tilt_Link">
    <inertial>
      <origin
        xyz="0.048937 -0.0205 2.3419E-17"
        rpy="0 0 0" />
      <mass
        value="0.1" />
      <inertia
        ixx="1.7921E-05"
        ixy="6.2701E-21"
        ixz="1.0872E-20"
        iyy="3.3393E-05"
        iyz="4.1427E-21"
        izz="4.7379E-05" />
    </inertial>
    <visual>
      <origin
        xyz="0 0 0"
        rpy="0 0 0" />
      <geometry>
        <mesh
          filename="package://mobi_head/urdf/meshes/Neck_Tilt_Link.STL" />
      </geometry>
      <material
        name="">
        <color
          rgba="0.79216 0.81961 0.93333 1" />
      </material>
    </visual>
    <collision>
      <origin
        xyz="0 0 0"
        rpy="0 0 0" />
      <geometry>
        <mesh
          filename="package://mobi_head/urdf/meshes/Neck_Tilt_Link.STL" />
      </geometry>
    </collision>
  </link>
  <joint
    name="Neck_Tilt_Joint"
    type="revolute">
    <origin
      xyz="0 0.0017774 -0.0205"
      rpy="-1.5708 -1.2246E-16 3.1416" />
    <parent
      link="Neck_Pan_Link" />
    <child
      link="Neck_Tilt_Link" />
    <axis
      xyz="0 1 0" />
    <limit
      lower="-1.5708"
      upper="1.5708"
      effort="3.1"
      velocity="3.14159265" />
  </joint>
  <link
    name="Head_Tilt_Link">
    <inertial>
      <origin
        xyz="-0.018556 -0.010813 -0.020532"
        rpy="0 0 0" />
      <mass
        value="0.18" />
      <inertia
        ixx="2.4256E-05"
        ixy="-3.8511E-07"
        ixz="-5.5741E-08"
        iyy="4.7591E-05"
        iyz="1.7779E-07"
        izz="5.4899E-05" />
    </inertial>
    <visual>
      <origin
        xyz="0 0 0"
        rpy="0 0 0" />
      <geometry>
        <mesh
          filename="package://mobi_head/urdf/meshes/Head_Tilt_Link.STL" />
      </geometry>
      <material
        name="">
        <color
          rgba="0.1569 0.1569 0.1569 1" />
      </material>
    </visual>
    <collision>
      <origin
        xyz="0 0 0"
        rpy="0 0 0" />
      <geometry>
        <mesh
          filename="package://mobi_head/urdf/meshes/Head_Tilt_Link.STL" />
      </geometry>
    </collision>
  </link>
  <joint
    name="Head_Tilt_Joint"
    type="revolute">
    <origin
      xyz="0.1 0 0"
      rpy="-1.5708 -1.5615 -1.1169E-13" />
    <parent
      link="Neck_Tilt_Link" />
    <child
      link="Head_Tilt_Link" />
    <axis
      xyz="0 0 -1" />
    <limit
      lower="-1.5708"
      upper="1.5708"
      effort="3.1"
      velocity="3.14159265" />
  </joint>
  <link
    name="Head_Roll_Link">
    <inertial>
      <origin
        xyz="2.235E-09 0.00062838 0.0046157"
        rpy="0 0 0" />
      <mass
        value="0.3" />
      <inertia
        ixx="0.00029035"
        ixy="1.7155E-09"
        ixz="-1.5765E-11"
        iyy="0.00079272"
        iyz="-2.6549E-06"
        izz="0.0010777" />
    </inertial>
    <visual>
      <origin
        xyz="0 0 0"
        rpy="0 3.14159265 0" />
      <geometry>
        <mesh
          filename="package://mobi_head/urdf/meshes/Head_Roll_Link.STL" />
      </geometry>
      <material
        name="">
        <color
          rgba="0 0 0 1" />
      </material>
    </visual>
    <collision>
      <origin
        xyz="0 0 0"
        rpy="0 3.14159265 0" />
      <geometry>
        <mesh
          filename="package://mobi_head/urdf/meshes/Head_Roll_Link.STL" />
      </geometry>
    </collision>
  </link>
  <joint
    name="Head_Roll_Joint"
    type="revolute">
    <origin
      xyz="-0.06285 0 -0.0205"
      rpy="3.1416 -1.5708 0" />
    <parent
      link="Head_Tilt_Link" />
    <child
      link="Head_Roll_Link" />
    <axis
      xyz="0 -0.0093137 -0.99996" />
    <limit
      lower="-1.5708"
      upper="1.5708"
      effort="3.1"
      velocity="3.14159265" />
  </joint>
  <link
    name="Screen_Link">
    <inertial>
      <origin
        xyz="0.0 0.0 0.0"
        rpy="0 0 0" />
      <mass
        value="0.001" />
      <inertia
        ixx="0.0"
        ixy="0.0"
        ixz="0.0"
        iyy="0.0"
        iyz="0.0"
        izz="0.0" />
    </inertial>
    <visual>
      <origin
        xyz="0 0 0"
        rpy="0 3.14159265 1.5708" />
      <geometry>
        <box size="0.09 0.15 0.001"/>
      </geometry>
      <material
        name="">
          <texture filename="package://mobi_head/urdf/mObi_neutral_expression_texture.png" />
      </material>
    </visual>
    <collision>
      <origin
        xyz="0 0 0"
        rpy="0 3.14159265 1.5708" />
      <geometry>
        <box size="0.09 0.15 0.001"/>
      </geometry>
    </collision>
  </link>
  <joint
    name="Screen_Joint"
    type="fixed">
    <origin
      xyz="0.0 0.0 -0.01"
      rpy="0 0 0" />
    <parent
      link="Head_Roll_Link" />
    <child
      link="Screen_Link" />
    <axis
      xyz="0 0 0" />
  </joint>
</robot>
